[2021-03-11 18:20:34 +0200] [1207] [INFO] Starting gunicorn 20.0.4
[2021-03-11 18:20:34 +0200] [1207] [ERROR] Invalid address: ('83.212.113.65', 5001)
[2021-03-11 18:20:34 +0200] [1207] [ERROR] Retrying in 1 second.
[2021-03-11 18:20:35 +0200] [1207] [ERROR] Invalid address: ('83.212.113.65', 5001)
[2021-03-11 18:20:35 +0200] [1207] [ERROR] Retrying in 1 second.
[2021-03-11 18:20:36 +0200] [1207] [ERROR] Invalid address: ('83.212.113.65', 5001)
[2021-03-11 18:20:36 +0200] [1207] [ERROR] Retrying in 1 second.
[2021-03-11 18:20:37 +0200] [1207] [ERROR] Invalid address: ('83.212.113.65', 5001)
[2021-03-11 18:20:37 +0200] [1207] [ERROR] Retrying in 1 second.
[2021-03-11 18:20:38 +0200] [1207] [ERROR] Invalid address: ('83.212.113.65', 5001)
[2021-03-11 18:20:38 +0200] [1207] [ERROR] Retrying in 1 second.
[2021-03-11 18:20:39 +0200] [1207] [ERROR] Can't connect to ('83.212.113.65', 5001)
[2021-03-11 18:23:42 +0200] [1530] [INFO] Starting gunicorn 20.0.4
[2021-03-11 18:23:42 +0200] [1530] [INFO] Listening at: http://139.91.183.96:5001 (1530)
[2021-03-11 18:23:42 +0200] [1530] [INFO] Using worker: sync
[2021-03-11 18:23:42 +0200] [1533] [INFO] Booting worker with pid: 1533
[2021-03-13 13:33:36 +0200] [10709] [INFO] Starting gunicorn 20.0.4
[2021-03-13 13:33:36 +0200] [10709] [INFO] Listening at: http://139.91.183.96:5001 (10709)
[2021-03-13 13:33:36 +0200] [10709] [INFO] Using worker: sync
[2021-03-13 13:33:36 +0200] [10712] [INFO] Booting worker with pid: 10712
[2021-03-13 14:56:28,410] ERROR in app: Exception on /answer [GET]
Traceback (most recent call last):
  File "/usr/local/lib/python3.6/dist-packages/flask/app.py", line 2447, in wsgi_app
    response = self.full_dispatch_request()
  File "/usr/local/lib/python3.6/dist-packages/flask/app.py", line 1952, in full_dispatch_request
    rv = self.handle_user_exception(e)
  File "/usr/local/lib/python3.6/dist-packages/flask/app.py", line 1821, in handle_user_exception
    reraise(exc_type, exc_value, tb)
  File "/usr/local/lib/python3.6/dist-packages/flask/_compat.py", line 39, in reraise
    raise value
  File "/usr/local/lib/python3.6/dist-packages/flask/app.py", line 1950, in full_dispatch_request
    rv = self.dispatch_request()
  File "/usr/local/lib/python3.6/dist-packages/flask/app.py", line 1936, in dispatch_request
    return self.view_functions[rule.endpoint](**req.view_args)
  File "/home/nicolaig/elas4rdf_qa/app.py", line 29, in api_answer
    entities = get_entities_from_elas4rdf(question)
  File "/home/nicolaig/elas4rdf_qa/entity_expansion.py", line 111, in get_entities_from_elas4rdf
    entities = [{'uri':e['entity'],'rdfs_comment':e['ext']['rdfs_comment']} for e in response_json['results']['entities']]
  File "/home/nicolaig/elas4rdf_qa/entity_expansion.py", line 111, in <listcomp>
    entities = [{'uri':e['entity'],'rdfs_comment':e['ext']['rdfs_comment']} for e in response_json['results']['entities']]
KeyError: 'rdfs_comment'
[2021-03-13 15:12:07,477] ERROR in app: Exception on /answer [GET]
Traceback (most recent call last):
  File "/usr/local/lib/python3.6/dist-packages/flask/app.py", line 2447, in wsgi_app
    response = self.full_dispatch_request()
  File "/usr/local/lib/python3.6/dist-packages/flask/app.py", line 1952, in full_dispatch_request
    rv = self.handle_user_exception(e)
  File "/usr/local/lib/python3.6/dist-packages/flask/app.py", line 1821, in handle_user_exception
    reraise(exc_type, exc_value, tb)
  File "/usr/local/lib/python3.6/dist-packages/flask/_compat.py", line 39, in reraise
    raise value
  File "/usr/local/lib/python3.6/dist-packages/flask/app.py", line 1950, in full_dispatch_request
    rv = self.dispatch_request()
  File "/usr/local/lib/python3.6/dist-packages/flask/app.py", line 1936, in dispatch_request
    return self.view_functions[rule.endpoint](**req.view_args)
  File "/home/nicolaig/elas4rdf_qa/app.py", line 29, in api_answer
    entities = get_entities_from_elas4rdf(question)
  File "/home/nicolaig/elas4rdf_qa/entity_expansion.py", line 111, in get_entities_from_elas4rdf
    entities = [{'uri':e['entity'],'rdfs_comment':e['ext']['rdfs_comment']} for e in response_json['results']['entities']]
  File "/home/nicolaig/elas4rdf_qa/entity_expansion.py", line 111, in <listcomp>
    entities = [{'uri':e['entity'],'rdfs_comment':e['ext']['rdfs_comment']} for e in response_json['results']['entities']]
KeyError: 'rdfs_comment'
[2021-03-13 15:14:00,823] ERROR in app: Exception on /answer [GET]
Traceback (most recent call last):
  File "/usr/local/lib/python3.6/dist-packages/flask/app.py", line 2447, in wsgi_app
    response = self.full_dispatch_request()
  File "/usr/local/lib/python3.6/dist-packages/flask/app.py", line 1952, in full_dispatch_request
    rv = self.handle_user_exception(e)
  File "/usr/local/lib/python3.6/dist-packages/flask/app.py", line 1821, in handle_user_exception
    reraise(exc_type, exc_value, tb)
  File "/usr/local/lib/python3.6/dist-packages/flask/_compat.py", line 39, in reraise
    raise value
  File "/usr/local/lib/python3.6/dist-packages/flask/app.py", line 1950, in full_dispatch_request
    rv = self.dispatch_request()
  File "/usr/local/lib/python3.6/dist-packages/flask/app.py", line 1936, in dispatch_request
    return self.view_functions[rule.endpoint](**req.view_args)
  File "/home/nicolaig/elas4rdf_qa/app.py", line 29, in api_answer
    entities = get_entities_from_elas4rdf(question)
  File "/home/nicolaig/elas4rdf_qa/entity_expansion.py", line 111, in get_entities_from_elas4rdf
    entities = [{'uri':e['entity'],'rdfs_comment':e['ext']['rdfs_comment']} for e in response_json['results']['entities']]
  File "/home/nicolaig/elas4rdf_qa/entity_expansion.py", line 111, in <listcomp>
    entities = [{'uri':e['entity'],'rdfs_comment':e['ext']['rdfs_comment']} for e in response_json['results']['entities']]
KeyError: 'rdfs_comment'
[2021-03-13 15:14:05,686] ERROR in app: Exception on /answer [GET]
Traceback (most recent call last):
  File "/usr/local/lib/python3.6/dist-packages/flask/app.py", line 2447, in wsgi_app
    response = self.full_dispatch_request()
  File "/usr/local/lib/python3.6/dist-packages/flask/app.py", line 1952, in full_dispatch_request
    rv = self.handle_user_exception(e)
  File "/usr/local/lib/python3.6/dist-packages/flask/app.py", line 1821, in handle_user_exception
    reraise(exc_type, exc_value, tb)
  File "/usr/local/lib/python3.6/dist-packages/flask/_compat.py", line 39, in reraise
    raise value
  File "/usr/local/lib/python3.6/dist-packages/flask/app.py", line 1950, in full_dispatch_request
    rv = self.dispatch_request()
  File "/usr/local/lib/python3.6/dist-packages/flask/app.py", line 1936, in dispatch_request
    return self.view_functions[rule.endpoint](**req.view_args)
  File "/home/nicolaig/elas4rdf_qa/app.py", line 29, in api_answer
    entities = get_entities_from_elas4rdf(question)
  File "/home/nicolaig/elas4rdf_qa/entity_expansion.py", line 111, in get_entities_from_elas4rdf
    entities = [{'uri':e['entity'],'rdfs_comment':e['ext']['rdfs_comment']} for e in response_json['results']['entities']]
  File "/home/nicolaig/elas4rdf_qa/entity_expansion.py", line 111, in <listcomp>
    entities = [{'uri':e['entity'],'rdfs_comment':e['ext']['rdfs_comment']} for e in response_json['results']['entities']]
KeyError: 'rdfs_comment'
[2021-03-13 15:25:58,942] ERROR in app: Exception on /answer [GET]
Traceback (most recent call last):
  File "/usr/local/lib/python3.6/dist-packages/flask/app.py", line 2447, in wsgi_app
    response = self.full_dispatch_request()
  File "/usr/local/lib/python3.6/dist-packages/flask/app.py", line 1952, in full_dispatch_request
    rv = self.handle_user_exception(e)
  File "/usr/local/lib/python3.6/dist-packages/flask/app.py", line 1821, in handle_user_exception
    reraise(exc_type, exc_value, tb)
  File "/usr/local/lib/python3.6/dist-packages/flask/_compat.py", line 39, in reraise
    raise value
  File "/usr/local/lib/python3.6/dist-packages/flask/app.py", line 1950, in full_dispatch_request
    rv = self.dispatch_request()
  File "/usr/local/lib/python3.6/dist-packages/flask/app.py", line 1936, in dispatch_request
    return self.view_functions[rule.endpoint](**req.view_args)
  File "/home/nicolaig/elas4rdf_qa/app.py", line 29, in api_answer
    entities = get_entities_from_elas4rdf(question)
  File "/home/nicolaig/elas4rdf_qa/entity_expansion.py", line 111, in get_entities_from_elas4rdf
    with open('debug.json',encoding='utf8') as output:
  File "/home/nicolaig/elas4rdf_qa/entity_expansion.py", line 111, in <listcomp>
    with open('debug.json',encoding='utf8') as output:
KeyError: 'rdfs_comment'
[2021-03-13 15:38:36 +0200] [42788] [INFO] Starting gunicorn 20.0.4
[2021-03-13 15:38:36 +0200] [42788] [INFO] Listening at: http://139.91.183.96:5001 (42788)
[2021-03-13 15:38:36 +0200] [42788] [INFO] Using worker: sync
[2021-03-13 15:38:36 +0200] [42791] [INFO] Booting worker with pid: 42791
[2021-03-13 15:38:51,829] ERROR in app: Exception on /answer [GET]
Traceback (most recent call last):
  File "/usr/local/lib/python3.6/dist-packages/flask/app.py", line 2447, in wsgi_app
    response = self.full_dispatch_request()
  File "/usr/local/lib/python3.6/dist-packages/flask/app.py", line 1952, in full_dispatch_request
    rv = self.handle_user_exception(e)
  File "/usr/local/lib/python3.6/dist-packages/flask/app.py", line 1821, in handle_user_exception
    reraise(exc_type, exc_value, tb)
  File "/usr/local/lib/python3.6/dist-packages/flask/_compat.py", line 39, in reraise
    raise value
  File "/usr/local/lib/python3.6/dist-packages/flask/app.py", line 1950, in full_dispatch_request
    rv = self.dispatch_request()
  File "/usr/local/lib/python3.6/dist-packages/flask/app.py", line 1936, in dispatch_request
    return self.view_functions[rule.endpoint](**req.view_args)
  File "/home/nicolaig/elas4rdf_qa/app.py", line 29, in api_answer
    entities = get_entities_from_elas4rdf(question)
  File "/home/nicolaig/elas4rdf_qa/entity_expansion.py", line 111, in get_entities_from_elas4rdf
    with open('debug.json',encoding='utf8') as output:
FileNotFoundError: [Errno 2] No such file or directory: 'debug.json'
[2021-03-13 15:40:35 +0200] [43113] [INFO] Starting gunicorn 20.0.4
[2021-03-13 15:40:35 +0200] [43113] [INFO] Listening at: http://139.91.183.96:5001 (43113)
[2021-03-13 15:40:35 +0200] [43113] [INFO] Using worker: sync
[2021-03-13 15:40:35 +0200] [43116] [INFO] Booting worker with pid: 43116
[2021-03-13 15:42:34,154] ERROR in app: Exception on /answer [GET]
Traceback (most recent call last):
  File "/usr/local/lib/python3.6/dist-packages/flask/app.py", line 2447, in wsgi_app
    response = self.full_dispatch_request()
  File "/usr/local/lib/python3.6/dist-packages/flask/app.py", line 1952, in full_dispatch_request
    rv = self.handle_user_exception(e)
  File "/usr/local/lib/python3.6/dist-packages/flask/app.py", line 1821, in handle_user_exception
    reraise(exc_type, exc_value, tb)
  File "/usr/local/lib/python3.6/dist-packages/flask/_compat.py", line 39, in reraise
    raise value
  File "/usr/local/lib/python3.6/dist-packages/flask/app.py", line 1950, in full_dispatch_request
    rv = self.dispatch_request()
  File "/usr/local/lib/python3.6/dist-packages/flask/app.py", line 1936, in dispatch_request
    return self.view_functions[rule.endpoint](**req.view_args)
  File "/home/nicolaig/elas4rdf_qa/app.py", line 29, in api_answer
    entities = get_entities_from_elas4rdf(question)
  File "/home/nicolaig/elas4rdf_qa/entity_expansion.py", line 111, in get_entities_from_elas4rdf
    with open('debug.json',encoding='utf8') as output:
FileNotFoundError: [Errno 2] No such file or directory: 'debug.json'
[2021-03-13 15:43:59 +0200] [43566] [INFO] Starting gunicorn 20.0.4
[2021-03-13 15:43:59 +0200] [43566] [INFO] Listening at: http://139.91.183.96:5001 (43566)
[2021-03-13 15:43:59 +0200] [43566] [INFO] Using worker: sync
[2021-03-13 15:43:59 +0200] [43569] [INFO] Booting worker with pid: 43569
[2021-03-13 15:44:14,548] ERROR in app: Exception on /answer [GET]
Traceback (most recent call last):
  File "/usr/local/lib/python3.6/dist-packages/flask/app.py", line 2447, in wsgi_app
    response = self.full_dispatch_request()
  File "/usr/local/lib/python3.6/dist-packages/flask/app.py", line 1952, in full_dispatch_request
    rv = self.handle_user_exception(e)
  File "/usr/local/lib/python3.6/dist-packages/flask/app.py", line 1821, in handle_user_exception
    reraise(exc_type, exc_value, tb)
  File "/usr/local/lib/python3.6/dist-packages/flask/_compat.py", line 39, in reraise
    raise value
  File "/usr/local/lib/python3.6/dist-packages/flask/app.py", line 1950, in full_dispatch_request
    rv = self.dispatch_request()
  File "/usr/local/lib/python3.6/dist-packages/flask/app.py", line 1936, in dispatch_request
    return self.view_functions[rule.endpoint](**req.view_args)
  File "/home/nicolaig/elas4rdf_qa/app.py", line 29, in api_answer
    entities = get_entities_from_elas4rdf(question)
  File "/home/nicolaig/elas4rdf_qa/entity_expansion.py", line 109, in get_entities_from_elas4rdf
    with open('debug.txt') as output:
FileNotFoundError: [Errno 2] No such file or directory: 'debug.txt'
[2021-03-13 15:46:50 +0200] [43930] [INFO] Starting gunicorn 20.0.4
[2021-03-13 15:46:50 +0200] [43930] [INFO] Listening at: http://139.91.183.96:5001 (43930)
[2021-03-13 15:46:50 +0200] [43930] [INFO] Using worker: sync
[2021-03-13 15:46:50 +0200] [43933] [INFO] Booting worker with pid: 43933
[2021-03-13 16:02:57,158] ERROR in app: Exception on /answer [GET]
Traceback (most recent call last):
  File "/usr/local/lib/python3.6/dist-packages/flask/app.py", line 2447, in wsgi_app
    response = self.full_dispatch_request()
  File "/usr/local/lib/python3.6/dist-packages/flask/app.py", line 1952, in full_dispatch_request
    rv = self.handle_user_exception(e)
  File "/usr/local/lib/python3.6/dist-packages/flask/app.py", line 1821, in handle_user_exception
    reraise(exc_type, exc_value, tb)
  File "/usr/local/lib/python3.6/dist-packages/flask/_compat.py", line 39, in reraise
    raise value
  File "/usr/local/lib/python3.6/dist-packages/flask/app.py", line 1950, in full_dispatch_request
    rv = self.dispatch_request()
  File "/usr/local/lib/python3.6/dist-packages/flask/app.py", line 1936, in dispatch_request
    return self.view_functions[rule.endpoint](**req.view_args)
  File "/home/nicolaig/elas4rdf_qa/app.py", line 29, in api_answer
    entities = get_entities_from_elas4rdf(question)
  File "/home/nicolaig/elas4rdf_qa/entity_expansion.py", line 112, in get_entities_from_elas4rdf
    entities = [{'uri':e['entity'],'rdfs_comment':e['ext']['rdfs_comment']} for e in response_json['results']['entities']]
  File "/home/nicolaig/elas4rdf_qa/entity_expansion.py", line 112, in <listcomp>
    entities = [{'uri':e['entity'],'rdfs_comment':e['ext']['rdfs_comment']} for e in response_json['results']['entities']]
KeyError: 'rdfs_comment'
[2021-03-13 16:05:10,316] ERROR in app: Exception on /answer [GET]
Traceback (most recent call last):
  File "/usr/local/lib/python3.6/dist-packages/flask/app.py", line 2447, in wsgi_app
    response = self.full_dispatch_request()
  File "/usr/local/lib/python3.6/dist-packages/flask/app.py", line 1952, in full_dispatch_request
    rv = self.handle_user_exception(e)
  File "/usr/local/lib/python3.6/dist-packages/flask/app.py", line 1821, in handle_user_exception
    reraise(exc_type, exc_value, tb)
  File "/usr/local/lib/python3.6/dist-packages/flask/_compat.py", line 39, in reraise
    raise value
  File "/usr/local/lib/python3.6/dist-packages/flask/app.py", line 1950, in full_dispatch_request
    rv = self.dispatch_request()
  File "/usr/local/lib/python3.6/dist-packages/flask/app.py", line 1936, in dispatch_request
    return self.view_functions[rule.endpoint](**req.view_args)
  File "/home/nicolaig/elas4rdf_qa/app.py", line 29, in api_answer
    entities = get_entities_from_elas4rdf(question)
  File "/home/nicolaig/elas4rdf_qa/entity_expansion.py", line 112, in get_entities_from_elas4rdf
    entities = [{'uri':e['entity'],'rdfs_comment':e['ext']['rdfs_comment']} for e in response_json['results']['entities']]
  File "/home/nicolaig/elas4rdf_qa/entity_expansion.py", line 112, in <listcomp>
    entities = [{'uri':e['entity'],'rdfs_comment':e['ext']['rdfs_comment']} for e in response_json['results']['entities']]
KeyError: 'rdfs_comment'
[2021-03-13 16:09:32,563] ERROR in app: Exception on /answer [GET]
Traceback (most recent call last):
  File "/usr/local/lib/python3.6/dist-packages/flask/app.py", line 2447, in wsgi_app
    response = self.full_dispatch_request()
  File "/usr/local/lib/python3.6/dist-packages/flask/app.py", line 1952, in full_dispatch_request
    rv = self.handle_user_exception(e)
  File "/usr/local/lib/python3.6/dist-packages/flask/app.py", line 1821, in handle_user_exception
    reraise(exc_type, exc_value, tb)
  File "/usr/local/lib/python3.6/dist-packages/flask/_compat.py", line 39, in reraise
    raise value
  File "/usr/local/lib/python3.6/dist-packages/flask/app.py", line 1950, in full_dispatch_request
    rv = self.dispatch_request()
  File "/usr/local/lib/python3.6/dist-packages/flask/app.py", line 1936, in dispatch_request
    return self.view_functions[rule.endpoint](**req.view_args)
  File "/home/nicolaig/elas4rdf_qa/app.py", line 29, in api_answer
    entities = get_entities_from_elas4rdf(question)
  File "/home/nicolaig/elas4rdf_qa/entity_expansion.py", line 112, in get_entities_from_elas4rdf
    entities = [{'uri':e['entity'],'rdfs_comment':e['ext']['rdfs_comment']} for e in response_json['results']['entities']]
  File "/home/nicolaig/elas4rdf_qa/entity_expansion.py", line 112, in <listcomp>
    entities = [{'uri':e['entity'],'rdfs_comment':e['ext']['rdfs_comment']} for e in response_json['results']['entities']]
KeyError: 'rdfs_comment'
[2021-03-13 16:48:03 +0200] [43930] [CRITICAL] WORKER TIMEOUT (pid:43933)
[2021-03-13 16:48:03 +0200] [43933] [INFO] Worker exiting (pid: 43933)
[2021-03-13 16:48:04 +0200] [27548] [INFO] Booting worker with pid: 27548
[2021-03-13 17:27:24,982] ERROR in app: Exception on /answer [GET]
Traceback (most recent call last):
  File "/usr/local/lib/python3.6/dist-packages/flask/app.py", line 2447, in wsgi_app
    response = self.full_dispatch_request()
  File "/usr/local/lib/python3.6/dist-packages/flask/app.py", line 1952, in full_dispatch_request
    rv = self.handle_user_exception(e)
  File "/usr/local/lib/python3.6/dist-packages/flask/app.py", line 1821, in handle_user_exception
    reraise(exc_type, exc_value, tb)
  File "/usr/local/lib/python3.6/dist-packages/flask/_compat.py", line 39, in reraise
    raise value
  File "/usr/local/lib/python3.6/dist-packages/flask/app.py", line 1950, in full_dispatch_request
    rv = self.dispatch_request()
  File "/usr/local/lib/python3.6/dist-packages/flask/app.py", line 1936, in dispatch_request
    return self.view_functions[rule.endpoint](**req.view_args)
  File "/home/nicolaig/elas4rdf_qa/app.py", line 29, in api_answer
    entities = get_entities_from_elas4rdf(question)
  File "/home/nicolaig/elas4rdf_qa/entity_expansion.py", line 113, in get_entities_from_elas4rdf
    for e in response_json['results']['entities']:
  File "/home/nicolaig/elas4rdf_qa/entity_expansion.py", line 113, in <listcomp>
    for e in response_json['results']['entities']:
KeyError: 'rdfs_comment'
[2021-03-13 17:30:16 +0200] [37257] [INFO] Booting worker with pid: 37257
[2021-03-13 17:30:21 +0200] [37344] [INFO] Starting gunicorn 20.0.4
[2021-03-13 17:30:21 +0200] [37344] [ERROR] Connection in use: ('139.91.183.96', 5001)
[2021-03-13 17:30:21 +0200] [37344] [ERROR] Retrying in 1 second.
[2021-03-13 17:30:22 +0200] [37344] [ERROR] Connection in use: ('139.91.183.96', 5001)
[2021-03-13 17:30:22 +0200] [37344] [ERROR] Retrying in 1 second.
[2021-03-13 17:30:23 +0200] [37344] [ERROR] Connection in use: ('139.91.183.96', 5001)
[2021-03-13 17:30:23 +0200] [37344] [ERROR] Retrying in 1 second.
[2021-03-13 17:30:24 +0200] [37344] [ERROR] Connection in use: ('139.91.183.96', 5001)
[2021-03-13 17:30:24 +0200] [37344] [ERROR] Retrying in 1 second.
[2021-03-13 17:30:25 +0200] [37344] [ERROR] Connection in use: ('139.91.183.96', 5001)
[2021-03-13 17:30:25 +0200] [37344] [ERROR] Retrying in 1 second.
[2021-03-13 17:30:26 +0200] [37344] [ERROR] Can't connect to ('139.91.183.96', 5001)
[2021-03-18 11:53:01 +0200] [32383] [INFO] Booting worker with pid: 32383
[2021-03-18 11:53:12 +0200] [32383] [INFO] Parent changed, shutting down: <Worker 32383>
[2021-03-18 11:53:12 +0200] [32383] [INFO] Worker exiting (pid: 32383)
[2021-03-18 11:57:30 +0200] [32998] [INFO] Starting gunicorn 20.0.4
[2021-03-18 11:57:30 +0200] [32998] [INFO] Listening at: http://139.91.183.96:5001 (32998)
[2021-03-18 11:57:30 +0200] [32998] [INFO] Using worker: sync
[2021-03-18 11:57:30 +0200] [33001] [INFO] Booting worker with pid: 33001
[2021-03-18 11:57:41,562] ERROR in app: Exception on /answer [GET]
Traceback (most recent call last):
  File "/usr/local/lib/python3.6/dist-packages/flask/app.py", line 2447, in wsgi_app
    response = self.full_dispatch_request()
  File "/usr/local/lib/python3.6/dist-packages/flask/app.py", line 1952, in full_dispatch_request
    rv = self.handle_user_exception(e)
  File "/usr/local/lib/python3.6/dist-packages/flask/app.py", line 1821, in handle_user_exception
    reraise(exc_type, exc_value, tb)
  File "/usr/local/lib/python3.6/dist-packages/flask/_compat.py", line 39, in reraise
    raise value
  File "/usr/local/lib/python3.6/dist-packages/flask/app.py", line 1950, in full_dispatch_request
    rv = self.dispatch_request()
  File "/usr/local/lib/python3.6/dist-packages/flask/app.py", line 1936, in dispatch_request
    return self.view_functions[rule.endpoint](**req.view_args)
  File "/home/nicolaig/elas4rdf_qa/app.py", line 29, in api_answer
    entities = get_entities_from_elas4rdf(question)
  File "/home/nicolaig/elas4rdf_qa/entity_expansion.py", line 112, in get_entities_from_elas4rdf
    for e in response_json['results']['entities']:
KeyError: 'entities'
[2021-03-21 11:21:15,842] ERROR in app: Exception on /answer [GET]
Traceback (most recent call last):
  File "/usr/local/lib/python3.6/dist-packages/flask/app.py", line 2447, in wsgi_app
    response = self.full_dispatch_request()
  File "/usr/local/lib/python3.6/dist-packages/flask/app.py", line 1952, in full_dispatch_request
    rv = self.handle_user_exception(e)
  File "/usr/local/lib/python3.6/dist-packages/flask/app.py", line 1821, in handle_user_exception
    reraise(exc_type, exc_value, tb)
  File "/usr/local/lib/python3.6/dist-packages/flask/_compat.py", line 39, in reraise
    raise value
  File "/usr/local/lib/python3.6/dist-packages/flask/app.py", line 1950, in full_dispatch_request
    rv = self.dispatch_request()
  File "/usr/local/lib/python3.6/dist-packages/flask/app.py", line 1936, in dispatch_request
    return self.view_functions[rule.endpoint](**req.view_args)
  File "/home/nicolaig/elas4rdf_qa/app.py", line 29, in api_answer
    entities = get_entities_from_elas4rdf(question)
  File "/home/nicolaig/elas4rdf_qa/entity_expansion.py", line 112, in get_entities_from_elas4rdf
    for e in response_json['results']['entities']:
KeyError: 'entities'
[2021-03-21 11:21:20,143] ERROR in app: Exception on /answer [GET]
Traceback (most recent call last):
  File "/usr/local/lib/python3.6/dist-packages/flask/app.py", line 2447, in wsgi_app
    response = self.full_dispatch_request()
  File "/usr/local/lib/python3.6/dist-packages/flask/app.py", line 1952, in full_dispatch_request
    rv = self.handle_user_exception(e)
  File "/usr/local/lib/python3.6/dist-packages/flask/app.py", line 1821, in handle_user_exception
    reraise(exc_type, exc_value, tb)
  File "/usr/local/lib/python3.6/dist-packages/flask/_compat.py", line 39, in reraise
    raise value
  File "/usr/local/lib/python3.6/dist-packages/flask/app.py", line 1950, in full_dispatch_request
    rv = self.dispatch_request()
  File "/usr/local/lib/python3.6/dist-packages/flask/app.py", line 1936, in dispatch_request
    return self.view_functions[rule.endpoint](**req.view_args)
  File "/home/nicolaig/elas4rdf_qa/app.py", line 29, in api_answer
    entities = get_entities_from_elas4rdf(question)
  File "/home/nicolaig/elas4rdf_qa/entity_expansion.py", line 112, in get_entities_from_elas4rdf
    for e in response_json['results']['entities']:
KeyError: 'entities'
[2021-03-21 11:28:20 +0200] [33001] [INFO] Parent changed, shutting down: <Worker 33001>
[2021-03-21 11:28:20 +0200] [33001] [INFO] Worker exiting (pid: 33001)
[2021-04-03 13:31:57 +0300] [54655] [INFO] Starting gunicorn 20.0.4
[2021-04-03 13:31:57 +0300] [54655] [INFO] Listening at: http://139.91.183.96:5001 (54655)
[2021-04-03 13:31:57 +0300] [54655] [INFO] Using worker: sync
[2021-04-03 13:31:57 +0300] [54658] [INFO] Booting worker with pid: 54658
[2021-04-03 19:19:18 +0300] [54655] [CRITICAL] WORKER TIMEOUT (pid:54658)
[2021-04-03 19:19:18 +0300] [54658] [INFO] Worker exiting (pid: 54658)
[2021-04-03 19:19:19 +0300] [12598] [INFO] Booting worker with pid: 12598
[2021-04-04 17:00:31 +0300] [14840] [INFO] Booting worker with pid: 14840
[2021-04-04 17:00:42 +0300] [14840] [ERROR] Exception in worker process
Traceback (most recent call last):
  File "/usr/local/lib/python3.6/dist-packages/gunicorn/arbiter.py", line 583, in spawn_worker
    worker.init_process()
  File "/usr/local/lib/python3.6/dist-packages/gunicorn/workers/base.py", line 119, in init_process
    self.load_wsgi()
  File "/usr/local/lib/python3.6/dist-packages/gunicorn/workers/base.py", line 144, in load_wsgi
    self.wsgi = self.app.wsgi()
  File "/usr/local/lib/python3.6/dist-packages/gunicorn/app/base.py", line 67, in wsgi
    self.callable = self.load()
  File "/usr/local/lib/python3.6/dist-packages/gunicorn/app/wsgiapp.py", line 49, in load
    return self.load_wsgiapp()
  File "/usr/local/lib/python3.6/dist-packages/gunicorn/app/wsgiapp.py", line 39, in load_wsgiapp
    return util.import_app(self.app_uri)
  File "/usr/local/lib/python3.6/dist-packages/gunicorn/util.py", line 358, in import_app
    mod = importlib.import_module(module)
  File "/usr/lib/python3.6/importlib/__init__.py", line 126, in import_module
    return _bootstrap._gcd_import(name[level:], package, level)
  File "<frozen importlib._bootstrap>", line 994, in _gcd_import
  File "<frozen importlib._bootstrap>", line 971, in _find_and_load
  File "<frozen importlib._bootstrap>", line 955, in _find_and_load_unlocked
  File "<frozen importlib._bootstrap>", line 665, in _load_unlocked
  File "<frozen importlib._bootstrap_external>", line 678, in exec_module
  File "<frozen importlib._bootstrap>", line 219, in _call_with_frames_removed
  File "/home/nicolaig/elas4rdf_qa/app.py", line 11, in <module>
    ae = AnswerExtraction()
  File "/home/nicolaig/elas4rdf_qa/answer_extraction.py", line 15, in __init__
    self.pipeline = pipeline(model=model,tokenizer=tokenizer,framework="pt",device=-1)
TypeError: pipeline() missing 1 required positional argument: 'task'
[2021-04-04 17:00:42 +0300] [14840] [INFO] Worker exiting (pid: 14840)
[2021-04-04 17:00:42 +0300] [54655] [INFO] Shutting down: Master
[2021-04-04 17:00:42 +0300] [54655] [INFO] Reason: Worker failed to boot.
[2021-04-04 17:04:37 +0300] [14997] [INFO] Starting gunicorn 20.0.4
[2021-04-04 17:04:37 +0300] [14997] [INFO] Listening at: http://139.91.183.96:5001 (14997)
[2021-04-04 17:04:37 +0300] [14997] [INFO] Using worker: sync
[2021-04-04 17:04:37 +0300] [15000] [INFO] Booting worker with pid: 15000
[2021-04-04 17:04:49 +0300] [15000] [ERROR] Exception in worker process
Traceback (most recent call last):
  File "/usr/local/lib/python3.6/dist-packages/gunicorn/arbiter.py", line 583, in spawn_worker
    worker.init_process()
  File "/usr/local/lib/python3.6/dist-packages/gunicorn/workers/base.py", line 119, in init_process
    self.load_wsgi()
  File "/usr/local/lib/python3.6/dist-packages/gunicorn/workers/base.py", line 144, in load_wsgi
    self.wsgi = self.app.wsgi()
  File "/usr/local/lib/python3.6/dist-packages/gunicorn/app/base.py", line 67, in wsgi
    self.callable = self.load()
  File "/usr/local/lib/python3.6/dist-packages/gunicorn/app/wsgiapp.py", line 49, in load
    return self.load_wsgiapp()
  File "/usr/local/lib/python3.6/dist-packages/gunicorn/app/wsgiapp.py", line 39, in load_wsgiapp
    return util.import_app(self.app_uri)
  File "/usr/local/lib/python3.6/dist-packages/gunicorn/util.py", line 358, in import_app
    mod = importlib.import_module(module)
  File "/usr/lib/python3.6/importlib/__init__.py", line 126, in import_module
    return _bootstrap._gcd_import(name[level:], package, level)
  File "<frozen importlib._bootstrap>", line 994, in _gcd_import
  File "<frozen importlib._bootstrap>", line 971, in _find_and_load
  File "<frozen importlib._bootstrap>", line 955, in _find_and_load_unlocked
  File "<frozen importlib._bootstrap>", line 665, in _load_unlocked
  File "<frozen importlib._bootstrap_external>", line 678, in exec_module
  File "<frozen importlib._bootstrap>", line 219, in _call_with_frames_removed
  File "/home/nicolaig/elas4rdf_qa/app.py", line 11, in <module>
    ae = AnswerExtraction()
  File "/home/nicolaig/elas4rdf_qa/answer_extraction.py", line 15, in __init__
    self.pipeline = pipeline(model=model,tokenizer=tokenizer,framework="pt",device=-1)
TypeError: pipeline() missing 1 required positional argument: 'task'
[2021-04-04 17:04:49 +0300] [15000] [INFO] Worker exiting (pid: 15000)
[2021-04-04 17:04:49 +0300] [14997] [INFO] Shutting down: Master
[2021-04-04 17:04:49 +0300] [14997] [INFO] Reason: Worker failed to boot.
[2021-04-04 17:05:35 +0300] [15132] [INFO] Starting gunicorn 20.0.4
[2021-04-04 17:05:35 +0300] [15132] [INFO] Listening at: http://139.91.183.96:5001 (15132)
[2021-04-04 17:05:35 +0300] [15132] [INFO] Using worker: sync
[2021-04-04 17:05:35 +0300] [15135] [INFO] Booting worker with pid: 15135
[2021-04-05 22:04:46 +0300] [23799] [INFO] Starting gunicorn 20.0.4
[2021-04-05 22:04:46 +0300] [23799] [INFO] Listening at: http://139.91.183.96:5001 (23799)
[2021-04-05 22:04:46 +0300] [23799] [INFO] Using worker: sync
[2021-04-05 22:04:46 +0300] [23802] [INFO] Booting worker with pid: 23802
[2021-04-07 18:51:40 +0300] [40252] [INFO] Starting gunicorn 20.0.4
[2021-04-07 18:51:40 +0300] [40252] [INFO] Listening at: http://139.91.183.96:5001 (40252)
[2021-04-07 18:51:40 +0300] [40252] [INFO] Using worker: sync
[2021-04-07 18:51:40 +0300] [40255] [INFO] Booting worker with pid: 40255
[2021-04-07 20:16:58 +0300] [40252] [CRITICAL] WORKER TIMEOUT (pid:40255)
[2021-04-07 20:16:58 +0300] [40255] [INFO] Worker exiting (pid: 40255)
[2021-04-07 20:16:59 +0300] [31214] [INFO] Booting worker with pid: 31214
[2021-04-07 21:18:09 +0300] [40252] [CRITICAL] WORKER TIMEOUT (pid:31214)
[2021-04-07 21:18:09 +0300] [31214] [INFO] Worker exiting (pid: 31214)
[2021-04-07 21:18:10 +0300] [16012] [INFO] Booting worker with pid: 16012
[2021-04-07 21:31:55 +0300] [40252] [CRITICAL] WORKER TIMEOUT (pid:16012)
[2021-04-07 21:31:55 +0300] [16012] [INFO] Worker exiting (pid: 16012)
[2021-04-07 21:31:55 +0300] [32413] [INFO] Booting worker with pid: 32413
[2021-06-22 12:24:47 +0300] [49375] [INFO] Booting worker with pid: 49375
[2021-06-22 12:25:16 +0300] [49375] [INFO] Parent changed, shutting down: <Worker 49375>
[2021-06-22 12:25:16 +0300] [49375] [INFO] Worker exiting (pid: 49375)
[2021-06-22 16:12:45 +0300] [62993] [INFO] Starting gunicorn 20.0.4
[2021-06-22 16:12:45 +0300] [62993] [ERROR] Invalid address: ('139.91.183', 5001)
[2021-06-22 16:12:45 +0300] [62993] [ERROR] Retrying in 1 second.
[2021-06-22 16:12:46 +0300] [62993] [ERROR] Invalid address: ('139.91.183', 5001)
[2021-06-22 16:12:46 +0300] [62993] [ERROR] Retrying in 1 second.
[2021-06-22 16:12:47 +0300] [62993] [ERROR] Invalid address: ('139.91.183', 5001)
[2021-06-22 16:12:47 +0300] [62993] [ERROR] Retrying in 1 second.
[2021-06-22 16:12:48 +0300] [62993] [ERROR] Invalid address: ('139.91.183', 5001)
[2021-06-22 16:12:48 +0300] [62993] [ERROR] Retrying in 1 second.
[2021-06-22 16:12:49 +0300] [62993] [ERROR] Invalid address: ('139.91.183', 5001)
[2021-06-22 16:12:49 +0300] [62993] [ERROR] Retrying in 1 second.
[2021-06-22 16:12:50 +0300] [62993] [ERROR] Can't connect to ('139.91.183', 5001)
[2021-06-22 16:14:26 +0300] [63105] [INFO] Starting gunicorn 20.0.4
[2021-06-22 16:14:26 +0300] [63105] [INFO] Listening at: http://139.91.183.96:5001 (63105)
[2021-06-22 16:14:26 +0300] [63105] [INFO] Using worker: sync
[2021-06-22 16:14:26 +0300] [63108] [INFO] Booting worker with pid: 63108
[2021-06-23 19:02:38 +0300] [58309] [INFO] Booting worker with pid: 58309
[2021-06-23 19:03:47 +0300] [59405] [INFO] Booting worker with pid: 59405
[2021-06-23 19:05:07 +0300] [60685] [INFO] Booting worker with pid: 60685
[2021-06-23 19:05:19 +0300] [60770] [INFO] Booting worker with pid: 60770
[2021-06-23 19:05:37 +0300] [60857] [INFO] Booting worker with pid: 60857
[2021-06-23 19:07:52 +0300] [62023] [INFO] Booting worker with pid: 62023
[2021-06-23 19:07:59 +0300] [62070] [INFO] Booting worker with pid: 62070
[2021-06-23 19:08:04 +0300] [62117] [INFO] Booting worker with pid: 62117
[2021-06-23 19:09:40 +0300] [62117] [INFO] Worker exiting (pid: 62117)
[2021-06-23 19:09:40 +0300] [63105] [INFO] Handling signal: term
[2021-06-23 19:09:41 +0300] [63105] [INFO] Shutting down: Master
[2021-06-23 19:15:07 +0300] [62640] [INFO] Starting gunicorn 20.0.4
[2021-06-23 19:15:07 +0300] [62640] [INFO] Listening at: http://139.91.183.96:5001 (62640)
[2021-06-23 19:15:07 +0300] [62640] [INFO] Using worker: sync
[2021-06-23 19:15:07 +0300] [62643] [INFO] Booting worker with pid: 62643
[2021-06-24 12:44:04 +0300] [24258] [INFO] Booting worker with pid: 24258
[2021-06-24 12:44:40 +0300] [24541] [INFO] Booting worker with pid: 24541
[2021-06-24 12:45:09 +0300] [24541] [INFO] Worker exiting (pid: 24541)
[2021-06-24 12:45:09 +0300] [62640] [INFO] Handling signal: term
[2021-06-24 12:45:09 +0300] [62640] [INFO] Shutting down: Master
[2021-06-24 12:46:05 +0300] [24869] [INFO] Starting gunicorn 20.0.4
[2021-06-24 12:46:05 +0300] [24869] [INFO] Listening at: http://139.91.183.96:5001 (24869)
[2021-06-24 12:46:05 +0300] [24869] [INFO] Using worker: sync
[2021-06-24 12:46:05 +0300] [24872] [INFO] Booting worker with pid: 24872
[2021-07-13 15:27:13,046] ERROR in app: Exception on /answer [GET]
Traceback (most recent call last):
  File "/usr/lib/python3/dist-packages/urllib3/connection.py", line 144, in _new_conn
    (self.host, self.port), self.timeout, **extra_kw)
  File "/usr/lib/python3/dist-packages/urllib3/util/connection.py", line 83, in create_connection
    raise err
  File "/usr/lib/python3/dist-packages/urllib3/util/connection.py", line 73, in create_connection
    sock.connect(sa)
ConnectionRefusedError: [Errno 111] Connection refused

During handling of the above exception, another exception occurred:

Traceback (most recent call last):
  File "/usr/lib/python3/dist-packages/urllib3/connectionpool.py", line 601, in urlopen
    chunked=chunked)
  File "/usr/lib/python3/dist-packages/urllib3/connectionpool.py", line 357, in _make_request
    conn.request(method, url, **httplib_request_kw)
  File "/usr/lib/python3.6/http/client.py", line 1281, in request
    self._send_request(method, url, body, headers, encode_chunked)
  File "/usr/lib/python3.6/http/client.py", line 1327, in _send_request
    self.endheaders(body, encode_chunked=encode_chunked)
  File "/usr/lib/python3.6/http/client.py", line 1276, in endheaders
    self._send_output(message_body, encode_chunked=encode_chunked)
  File "/usr/lib/python3.6/http/client.py", line 1042, in _send_output
    self.send(msg)
  File "/usr/lib/python3.6/http/client.py", line 980, in send
    self.connect()
  File "/usr/lib/python3/dist-packages/urllib3/connection.py", line 169, in connect
    conn = self._new_conn()
  File "/usr/lib/python3/dist-packages/urllib3/connection.py", line 153, in _new_conn
    self, "Failed to establish a new connection: %s" % e)
urllib3.exceptions.NewConnectionError: <urllib3.connection.HTTPConnection object at 0x7f0a0a841828>: Failed to establish a new connection: [Errno 111] Connection refused

During handling of the above exception, another exception occurred:

Traceback (most recent call last):
  File "/usr/lib/python3/dist-packages/requests/adapters.py", line 440, in send
    timeout=timeout
  File "/usr/lib/python3/dist-packages/urllib3/connectionpool.py", line 639, in urlopen
    _stacktrace=sys.exc_info()[2])
  File "/usr/lib/python3/dist-packages/urllib3/util/retry.py", line 398, in increment
    raise MaxRetryError(_pool, url, error or ResponseError(cause))
urllib3.exceptions.MaxRetryError: HTTPConnectionPool(host='dbpedia.org', port=80): Max retries exceeded with url: /sparql?query=select+distinct+str%28%3Fpl%29+as+%3FpLabel+%3Fa+where+%7B%3Chttp%3A%2F%2Fdbpedia.org%2Fresource%2FLisbon%3E+%3Fp+%3Fa+.+%3Fp+rdfs%3Alabel+%3Fpl+.+%3Chttp%3A%2F%2Fdbpedia.org%2Fontology%2FPoliticalParty%3E+owl%3AequivalentClass+%3Feq+.+%3Fa+rdf%3Atype+%3Feq+.+FILTER%28lang%28%3Fpl%29+%3D+%27en%27+%7C%7C+lang%28%3Fpl%29+%3D+%27%27%29+%7D&default-graph-uri=http%3A%2F%2Fdbpedia.org (Caused by NewConnectionError('<urllib3.connection.HTTPConnection object at 0x7f0a0a841828>: Failed to establish a new connection: [Errno 111] Connection refused',))

During handling of the above exception, another exception occurred:

Traceback (most recent call last):
  File "/usr/local/lib/python3.6/dist-packages/flask/app.py", line 2447, in wsgi_app
    response = self.full_dispatch_request()
  File "/usr/local/lib/python3.6/dist-packages/flask/app.py", line 1952, in full_dispatch_request
    rv = self.handle_user_exception(e)
  File "/usr/local/lib/python3.6/dist-packages/flask/app.py", line 1821, in handle_user_exception
    reraise(exc_type, exc_value, tb)
  File "/usr/local/lib/python3.6/dist-packages/flask/_compat.py", line 39, in reraise
    raise value
  File "/usr/local/lib/python3.6/dist-packages/flask/app.py", line 1950, in full_dispatch_request
    rv = self.dispatch_request()
  File "/usr/local/lib/python3.6/dist-packages/flask/app.py", line 1936, in dispatch_request
    return self.view_functions[rule.endpoint](**req.view_args)
  File "/home/nicolaig/elas4rdf_qa/app.py", line 54, in api_answer
    entities, found_category, found_types[0])
  File "/home/nicolaig/elas4rdf_qa/answer_extraction.py", line 42, in extend_entities
    sentences = expansion.resource_sentences(e['uri'],type_uri)
  File "/home/nicolaig/elas4rdf_qa/entity_expansion.py", line 47, in resource_sentences
    response = sparql_query(query_string_o)
  File "/home/nicolaig/elas4rdf_qa/entity_expansion.py", line 20, in sparql_query
    response = requests.get(url,params=payload,headers=headers)
  File "/usr/lib/python3/dist-packages/requests/api.py", line 72, in get
    return request('get', url, params=params, **kwargs)
  File "/usr/lib/python3/dist-packages/requests/api.py", line 58, in request
    return session.request(method=method, url=url, **kwargs)
  File "/usr/lib/python3/dist-packages/requests/sessions.py", line 520, in request
    resp = self.send(prep, **send_kwargs)
  File "/usr/lib/python3/dist-packages/requests/sessions.py", line 630, in send
    r = adapter.send(request, **kwargs)
  File "/usr/lib/python3/dist-packages/requests/adapters.py", line 508, in send
    raise ConnectionError(e, request=request)
requests.exceptions.ConnectionError: HTTPConnectionPool(host='dbpedia.org', port=80): Max retries exceeded with url: /sparql?query=select+distinct+str%28%3Fpl%29+as+%3FpLabel+%3Fa+where+%7B%3Chttp%3A%2F%2Fdbpedia.org%2Fresource%2FLisbon%3E+%3Fp+%3Fa+.+%3Fp+rdfs%3Alabel+%3Fpl+.+%3Chttp%3A%2F%2Fdbpedia.org%2Fontology%2FPoliticalParty%3E+owl%3AequivalentClass+%3Feq+.+%3Fa+rdf%3Atype+%3Feq+.+FILTER%28lang%28%3Fpl%29+%3D+%27en%27+%7C%7C+lang%28%3Fpl%29+%3D+%27%27%29+%7D&default-graph-uri=http%3A%2F%2Fdbpedia.org (Caused by NewConnectionError('<urllib3.connection.HTTPConnection object at 0x7f0a0a841828>: Failed to establish a new connection: [Errno 111] Connection refused',))
[2021-07-19 19:03:21 +0300] [7406] [INFO] Starting gunicorn 20.0.4
[2021-07-19 19:03:21 +0300] [7406] [INFO] Listening at: http://139.91.183.96:5001 (7406)
[2021-07-19 19:03:21 +0300] [7406] [INFO] Using worker: sync
[2021-07-19 19:03:21 +0300] [7409] [INFO] Booting worker with pid: 7409
[2021-07-20 12:22:46 +0300] [14313] [INFO] Starting gunicorn 20.0.4
[2021-07-20 12:22:46 +0300] [14313] [INFO] Listening at: http://139.91.183.96:5001 (14313)
[2021-07-20 12:22:46 +0300] [14313] [INFO] Using worker: sync
[2021-07-20 12:22:46 +0300] [14316] [INFO] Booting worker with pid: 14316
[2021-07-20 12:29:17 +0300] [24066] [INFO] Starting gunicorn 20.0.4
[2021-07-20 12:29:17 +0300] [24066] [INFO] Listening at: http://139.91.183.96:5020 (24066)
[2021-07-20 12:29:17 +0300] [24066] [INFO] Using worker: sync
[2021-07-20 12:29:17 +0300] [24069] [INFO] Booting worker with pid: 24069
[2021-07-20 12:34:43 +0300] [24069] [INFO] Parent changed, shutting down: <Worker 24069>
[2021-07-20 12:34:43 +0300] [24069] [INFO] Worker exiting (pid: 24069)
[2021-07-20 12:43:57 +0300] [14313] [CRITICAL] WORKER TIMEOUT (pid:14316)
[2021-07-20 12:43:57 +0300] [14316] [INFO] Worker exiting (pid: 14316)
[2021-07-20 12:43:58 +0300] [50741] [INFO] Booting worker with pid: 50741
